[2025-10-01T04:29:19.777+0000] {local_task_job_runner.py:123} INFO - ::group::Pre task execution logs
[2025-10-01T04:29:19.791+0000] {taskinstance.py:2612} INFO - Dependencies all met for dep_context=non-requeueable deps ti=<TaskInstance: movie_data_pipeline.upload_to_minio manual__2025-10-01T04:24:12.952139+00:00 [queued]>
[2025-10-01T04:29:19.798+0000] {taskinstance.py:2612} INFO - Dependencies all met for dep_context=requeueable deps ti=<TaskInstance: movie_data_pipeline.upload_to_minio manual__2025-10-01T04:24:12.952139+00:00 [queued]>
[2025-10-01T04:29:19.799+0000] {taskinstance.py:2865} INFO - Starting attempt 2 of 2
[2025-10-01T04:29:19.810+0000] {taskinstance.py:2888} INFO - Executing <Task(PythonOperator): upload_to_minio> on 2025-10-01 04:24:12.952139+00:00
[2025-10-01T04:29:19.817+0000] {warnings.py:112} WARNING - /home/***/.local/lib/python3.12/site-packages/***/task/task_runner/standard_task_runner.py:70: DeprecationWarning: This process (pid=64) is multi-threaded, use of fork() may lead to deadlocks in the child.
  pid = os.fork()

[2025-10-01T04:29:19.819+0000] {standard_task_runner.py:72} INFO - Started process 66 to run task
[2025-10-01T04:29:19.819+0000] {standard_task_runner.py:104} INFO - Running: ['***', 'tasks', 'run', 'movie_data_pipeline', 'upload_to_minio', 'manual__2025-10-01T04:24:12.952139+00:00', '--job-id', '32', '--raw', '--subdir', 'DAGS_FOLDER/movie_pipeline.py', '--cfg-path', '/tmp/tmp9hzhocc5']
[2025-10-01T04:29:19.820+0000] {standard_task_runner.py:105} INFO - Job 32: Subtask upload_to_minio
[2025-10-01T04:29:19.877+0000] {task_command.py:467} INFO - Running <TaskInstance: movie_data_pipeline.upload_to_minio manual__2025-10-01T04:24:12.952139+00:00 [running]> on host 1b7dadb2e4f9
[2025-10-01T04:29:19.949+0000] {taskinstance.py:3131} INFO - Exporting env vars: AIRFLOW_CTX_DAG_OWNER='***' AIRFLOW_CTX_DAG_ID='movie_data_pipeline' AIRFLOW_CTX_TASK_ID='upload_to_minio' AIRFLOW_CTX_EXECUTION_DATE='2025-10-01T04:24:12.952139+00:00' AIRFLOW_CTX_TRY_NUMBER='2' AIRFLOW_CTX_DAG_RUN_ID='manual__2025-10-01T04:24:12.952139+00:00'
[2025-10-01T04:29:19.951+0000] {logging_mixin.py:190} INFO - Task instance is in running state
[2025-10-01T04:29:19.952+0000] {logging_mixin.py:190} INFO -  Previous state of the Task instance: queued
[2025-10-01T04:29:19.952+0000] {logging_mixin.py:190} INFO - Current task name:upload_to_minio state:running start_date:2025-10-01 04:29:19.791968+00:00
[2025-10-01T04:29:19.953+0000] {logging_mixin.py:190} INFO - Dag name:movie_data_pipeline and current dag run status:running
[2025-10-01T04:29:19.953+0000] {taskinstance.py:731} INFO - ::endgroup::
[2025-10-01T04:29:20.093+0000] {logging_mixin.py:190} INFO - ⚠️ Bucket movie-bucket not found. Creating...
[2025-10-01T04:29:20.102+0000] {logging_mixin.py:190} INFO - ❌ Error creating bucket: An error occurred (InvalidAccessKeyId) when calling the CreateBucket operation: The Access Key Id you provided does not exist in our records.
[2025-10-01T04:29:20.103+0000] {taskinstance.py:3310} ERROR - Task failed with exception
Traceback (most recent call last):
  File "/opt/airflow/dags/movie_pipeline.py", line 62, in upload_to_minio
    s3.head_bucket(Bucket=MINIO_BUCKET)
  File "/home/airflow/.local/lib/python3.12/site-packages/botocore/client.py", line 569, in _api_call
    return self._make_api_call(operation_name, kwargs)
           ^^^^^^^^^^^^^^^^^^^^^^^^^^^^^^^^^^^^^^^^^^^
  File "/home/airflow/.local/lib/python3.12/site-packages/botocore/client.py", line 1023, in _make_api_call
    raise error_class(parsed_response, operation_name)
botocore.exceptions.ClientError: An error occurred (403) when calling the HeadBucket operation: Forbidden

During handling of the above exception, another exception occurred:

Traceback (most recent call last):
  File "/home/airflow/.local/lib/python3.12/site-packages/airflow/models/taskinstance.py", line 767, in _execute_task
    result = _execute_callable(context=context, **execute_callable_kwargs)
             ^^^^^^^^^^^^^^^^^^^^^^^^^^^^^^^^^^^^^^^^^^^^^^^^^^^^^^^^^^^^^
  File "/home/airflow/.local/lib/python3.12/site-packages/airflow/models/taskinstance.py", line 733, in _execute_callable
    return ExecutionCallableRunner(
           ^^^^^^^^^^^^^^^^^^^^^^^^
  File "/home/airflow/.local/lib/python3.12/site-packages/airflow/utils/operator_helpers.py", line 252, in run
    return self.func(*args, **kwargs)
           ^^^^^^^^^^^^^^^^^^^^^^^^^^
  File "/home/airflow/.local/lib/python3.12/site-packages/airflow/models/baseoperator.py", line 406, in wrapper
    return func(self, *args, **kwargs)
           ^^^^^^^^^^^^^^^^^^^^^^^^^^^
  File "/home/airflow/.local/lib/python3.12/site-packages/airflow/operators/python.py", line 238, in execute
    return_value = self.execute_callable()
                   ^^^^^^^^^^^^^^^^^^^^^^^
  File "/home/airflow/.local/lib/python3.12/site-packages/airflow/operators/python.py", line 256, in execute_callable
    return runner.run(*self.op_args, **self.op_kwargs)
           ^^^^^^^^^^^^^^^^^^^^^^^^^^^^^^^^^^^^^^^^^^^
  File "/home/airflow/.local/lib/python3.12/site-packages/airflow/utils/operator_helpers.py", line 252, in run
    return self.func(*args, **kwargs)
           ^^^^^^^^^^^^^^^^^^^^^^^^^^
  File "/opt/airflow/dags/movie_pipeline.py", line 66, in upload_to_minio
    s3.create_bucket(Bucket=MINIO_BUCKET)
  File "/home/airflow/.local/lib/python3.12/site-packages/botocore/client.py", line 569, in _api_call
    return self._make_api_call(operation_name, kwargs)
           ^^^^^^^^^^^^^^^^^^^^^^^^^^^^^^^^^^^^^^^^^^^
  File "/home/airflow/.local/lib/python3.12/site-packages/botocore/client.py", line 1023, in _make_api_call
    raise error_class(parsed_response, operation_name)
botocore.exceptions.ClientError: An error occurred (InvalidAccessKeyId) when calling the CreateBucket operation: The Access Key Id you provided does not exist in our records.
[2025-10-01T04:29:20.113+0000] {logging_mixin.py:190} INFO - Task instance in failure state
[2025-10-01T04:29:20.114+0000] {logging_mixin.py:190} INFO - Task start:2025-10-01 04:29:19.791968+00:00 end:2025-10-01 04:29:20.113125+00:00 duration:0.321157
[2025-10-01T04:29:20.114+0000] {logging_mixin.py:190} INFO - Task:<Task(PythonOperator): upload_to_minio> dag:<DAG: movie_data_pipeline> dagrun:<DagRun movie_data_pipeline @ 2025-10-01 04:24:12.952139+00:00: manual__2025-10-01T04:24:12.952139+00:00, state:running, queued_at: 2025-10-01 04:24:12.977345+00:00. externally triggered: True>
[2025-10-01T04:29:20.115+0000] {logging_mixin.py:190} INFO - Failure caused by An error occurred (InvalidAccessKeyId) when calling the CreateBucket operation: The Access Key Id you provided does not exist in our records.
[2025-10-01T04:29:20.115+0000] {taskinstance.py:1225} INFO - Marking task as FAILED. dag_id=movie_data_pipeline, task_id=upload_to_minio, run_id=manual__2025-10-01T04:24:12.952139+00:00, execution_date=20251001T042412, start_date=20251001T042919, end_date=20251001T042920
[2025-10-01T04:29:20.128+0000] {taskinstance.py:340} INFO - ::group::Post task execution logs
[2025-10-01T04:29:20.128+0000] {standard_task_runner.py:124} ERROR - Failed to execute job 32 for task upload_to_minio (An error occurred (InvalidAccessKeyId) when calling the CreateBucket operation: The Access Key Id you provided does not exist in our records.; 66)
Traceback (most recent call last):
  File "/opt/airflow/dags/movie_pipeline.py", line 62, in upload_to_minio
    s3.head_bucket(Bucket=MINIO_BUCKET)
  File "/home/airflow/.local/lib/python3.12/site-packages/botocore/client.py", line 569, in _api_call
    return self._make_api_call(operation_name, kwargs)
           ^^^^^^^^^^^^^^^^^^^^^^^^^^^^^^^^^^^^^^^^^^^
  File "/home/airflow/.local/lib/python3.12/site-packages/botocore/client.py", line 1023, in _make_api_call
    raise error_class(parsed_response, operation_name)
botocore.exceptions.ClientError: An error occurred (403) when calling the HeadBucket operation: Forbidden

During handling of the above exception, another exception occurred:

Traceback (most recent call last):
  File "/home/airflow/.local/lib/python3.12/site-packages/airflow/task/task_runner/standard_task_runner.py", line 117, in _start_by_fork
    ret = args.func(args, dag=self.dag)
          ^^^^^^^^^^^^^^^^^^^^^^^^^^^^^
  File "/home/airflow/.local/lib/python3.12/site-packages/airflow/cli/cli_config.py", line 49, in command
    return func(*args, **kwargs)
           ^^^^^^^^^^^^^^^^^^^^^
  File "/home/airflow/.local/lib/python3.12/site-packages/airflow/utils/cli.py", line 115, in wrapper
    return f(*args, **kwargs)
           ^^^^^^^^^^^^^^^^^^
  File "/home/airflow/.local/lib/python3.12/site-packages/airflow/cli/commands/task_command.py", line 483, in task_run
    task_return_code = _run_task_by_selected_method(args, _dag, ti)
                       ^^^^^^^^^^^^^^^^^^^^^^^^^^^^^^^^^^^^^^^^^^^^
  File "/home/airflow/.local/lib/python3.12/site-packages/airflow/cli/commands/task_command.py", line 256, in _run_task_by_selected_method
    return _run_raw_task(args, ti)
           ^^^^^^^^^^^^^^^^^^^^^^^
  File "/home/airflow/.local/lib/python3.12/site-packages/airflow/cli/commands/task_command.py", line 341, in _run_raw_task
    return ti._run_raw_task(
           ^^^^^^^^^^^^^^^^^
  File "/home/airflow/.local/lib/python3.12/site-packages/airflow/utils/session.py", line 97, in wrapper
    return func(*args, session=session, **kwargs)
           ^^^^^^^^^^^^^^^^^^^^^^^^^^^^^^^^^^^^^^
  File "/home/airflow/.local/lib/python3.12/site-packages/airflow/models/taskinstance.py", line 3004, in _run_raw_task
    return _run_raw_task(
           ^^^^^^^^^^^^^^
  File "/home/airflow/.local/lib/python3.12/site-packages/airflow/models/taskinstance.py", line 273, in _run_raw_task
    TaskInstance._execute_task_with_callbacks(
  File "/home/airflow/.local/lib/python3.12/site-packages/airflow/models/taskinstance.py", line 3158, in _execute_task_with_callbacks
    result = self._execute_task(context, task_orig)
             ^^^^^^^^^^^^^^^^^^^^^^^^^^^^^^^^^^^^^^
  File "/home/airflow/.local/lib/python3.12/site-packages/airflow/models/taskinstance.py", line 3182, in _execute_task
    return _execute_task(self, context, task_orig)
           ^^^^^^^^^^^^^^^^^^^^^^^^^^^^^^^^^^^^^^^
  File "/home/airflow/.local/lib/python3.12/site-packages/airflow/models/taskinstance.py", line 767, in _execute_task
    result = _execute_callable(context=context, **execute_callable_kwargs)
             ^^^^^^^^^^^^^^^^^^^^^^^^^^^^^^^^^^^^^^^^^^^^^^^^^^^^^^^^^^^^^
  File "/home/airflow/.local/lib/python3.12/site-packages/airflow/models/taskinstance.py", line 733, in _execute_callable
    return ExecutionCallableRunner(
           ^^^^^^^^^^^^^^^^^^^^^^^^
  File "/home/airflow/.local/lib/python3.12/site-packages/airflow/utils/operator_helpers.py", line 252, in run
    return self.func(*args, **kwargs)
           ^^^^^^^^^^^^^^^^^^^^^^^^^^
  File "/home/airflow/.local/lib/python3.12/site-packages/airflow/models/baseoperator.py", line 406, in wrapper
    return func(self, *args, **kwargs)
           ^^^^^^^^^^^^^^^^^^^^^^^^^^^
  File "/home/airflow/.local/lib/python3.12/site-packages/airflow/operators/python.py", line 238, in execute
    return_value = self.execute_callable()
                   ^^^^^^^^^^^^^^^^^^^^^^^
  File "/home/airflow/.local/lib/python3.12/site-packages/airflow/operators/python.py", line 256, in execute_callable
    return runner.run(*self.op_args, **self.op_kwargs)
           ^^^^^^^^^^^^^^^^^^^^^^^^^^^^^^^^^^^^^^^^^^^
  File "/home/airflow/.local/lib/python3.12/site-packages/airflow/utils/operator_helpers.py", line 252, in run
    return self.func(*args, **kwargs)
           ^^^^^^^^^^^^^^^^^^^^^^^^^^
  File "/opt/airflow/dags/movie_pipeline.py", line 66, in upload_to_minio
    s3.create_bucket(Bucket=MINIO_BUCKET)
  File "/home/airflow/.local/lib/python3.12/site-packages/botocore/client.py", line 569, in _api_call
    return self._make_api_call(operation_name, kwargs)
           ^^^^^^^^^^^^^^^^^^^^^^^^^^^^^^^^^^^^^^^^^^^
  File "/home/airflow/.local/lib/python3.12/site-packages/botocore/client.py", line 1023, in _make_api_call
    raise error_class(parsed_response, operation_name)
botocore.exceptions.ClientError: An error occurred (InvalidAccessKeyId) when calling the CreateBucket operation: The Access Key Id you provided does not exist in our records.
[2025-10-01T04:29:20.154+0000] {local_task_job_runner.py:266} INFO - Task exited with return code 1
[2025-10-01T04:29:20.175+0000] {taskinstance.py:3900} INFO - 0 downstream tasks scheduled from follow-on schedule check
[2025-10-01T04:29:20.179+0000] {local_task_job_runner.py:245} INFO - ::endgroup::
